[2022-10-06 13:05:41,268] ERROR [django.request:241] Internal Server Error: /my-account/
Traceback (most recent call last):
  File "C:\Users\kamro\Desktop\sms_a\venv\lib\site-packages\django\core\handlers\exception.py", line 55, in inner
    response = get_response(request)
  File "C:\Users\kamro\Desktop\sms_a\venv\lib\site-packages\django\core\handlers\base.py", line 197, in _get_response
    response = wrapped_callback(request, *callback_args, **callback_kwargs)
  File "C:\Users\kamro\Desktop\sms_a\users\views.py", line 79, in loginView
    return render(request, 'users/login.html', context)
  File "C:\Users\kamro\Desktop\sms_a\venv\lib\site-packages\django\shortcuts.py", line 24, in render
    content = loader.render_to_string(template_name, context, request, using=using)
  File "C:\Users\kamro\Desktop\sms_a\venv\lib\site-packages\django\template\loader.py", line 61, in render_to_string
    template = get_template(template_name, using=using)
  File "C:\Users\kamro\Desktop\sms_a\venv\lib\site-packages\django\template\loader.py", line 15, in get_template
    return engine.get_template(template_name)
  File "C:\Users\kamro\Desktop\sms_a\venv\lib\site-packages\django\template\backends\django.py", line 34, in get_template
    return Template(self.engine.get_template(template_name), self)
  File "C:\Users\kamro\Desktop\sms_a\venv\lib\site-packages\django\template\engine.py", line 175, in get_template
    template, origin = self.find_template(template_name)
  File "C:\Users\kamro\Desktop\sms_a\venv\lib\site-packages\django\template\engine.py", line 157, in find_template
    template = loader.get_template(name, skip=skip)
  File "C:\Users\kamro\Desktop\sms_a\venv\lib\site-packages\django\template\loaders\cached.py", line 57, in get_template
    template = super().get_template(template_name, skip)
  File "C:\Users\kamro\Desktop\sms_a\venv\lib\site-packages\django\template\loaders\base.py", line 28, in get_template
    return Template(
  File "C:\Users\kamro\Desktop\sms_a\venv\lib\site-packages\django\template\base.py", line 154, in __init__
    self.nodelist = self.compile_nodelist()
  File "C:\Users\kamro\Desktop\sms_a\venv\lib\site-packages\django\template\base.py", line 200, in compile_nodelist
    return parser.parse()
  File "C:\Users\kamro\Desktop\sms_a\venv\lib\site-packages\django\template\base.py", line 513, in parse
    raise self.error(token, e)
  File "C:\Users\kamro\Desktop\sms_a\venv\lib\site-packages\django\template\base.py", line 511, in parse
    compiled_result = compile_func(self, token)
  File "C:\Users\kamro\Desktop\sms_a\venv\lib\site-packages\django\template\defaulttags.py", line 974, in do_if
    raise TemplateSyntaxError(
django.template.exceptions.TemplateSyntaxError: Malformed template tag at line 49: "else page == 'register'"
[2022-10-06 13:05:41,333] ERROR [django.server:187] "GET /my-account/ HTTP/1.1" 500 158308
[2022-10-06 13:08:28,924] ERROR [django.request:241] Internal Server Error: /my-account/
Traceback (most recent call last):
  File "C:\Users\kamro\Desktop\sms_a\venv\lib\site-packages\django\core\handlers\exception.py", line 55, in inner
    response = get_response(request)
  File "C:\Users\kamro\Desktop\sms_a\venv\lib\site-packages\django\core\handlers\base.py", line 197, in _get_response
    response = wrapped_callback(request, *callback_args, **callback_kwargs)
  File "C:\Users\kamro\Desktop\sms_a\users\views.py", line 79, in loginView
    return render(request, 'users/login.html', context)
  File "C:\Users\kamro\Desktop\sms_a\venv\lib\site-packages\django\shortcuts.py", line 24, in render
    content = loader.render_to_string(template_name, context, request, using=using)
  File "C:\Users\kamro\Desktop\sms_a\venv\lib\site-packages\django\template\loader.py", line 61, in render_to_string
    template = get_template(template_name, using=using)
  File "C:\Users\kamro\Desktop\sms_a\venv\lib\site-packages\django\template\loader.py", line 15, in get_template
    return engine.get_template(template_name)
  File "C:\Users\kamro\Desktop\sms_a\venv\lib\site-packages\django\template\backends\django.py", line 34, in get_template
    return Template(self.engine.get_template(template_name), self)
  File "C:\Users\kamro\Desktop\sms_a\venv\lib\site-packages\django\template\engine.py", line 175, in get_template
    template, origin = self.find_template(template_name)
  File "C:\Users\kamro\Desktop\sms_a\venv\lib\site-packages\django\template\engine.py", line 157, in find_template
    template = loader.get_template(name, skip=skip)
  File "C:\Users\kamro\Desktop\sms_a\venv\lib\site-packages\django\template\loaders\cached.py", line 57, in get_template
    template = super().get_template(template_name, skip)
  File "C:\Users\kamro\Desktop\sms_a\venv\lib\site-packages\django\template\loaders\base.py", line 28, in get_template
    return Template(
  File "C:\Users\kamro\Desktop\sms_a\venv\lib\site-packages\django\template\base.py", line 154, in __init__
    self.nodelist = self.compile_nodelist()
  File "C:\Users\kamro\Desktop\sms_a\venv\lib\site-packages\django\template\base.py", line 200, in compile_nodelist
    return parser.parse()
  File "C:\Users\kamro\Desktop\sms_a\venv\lib\site-packages\django\template\base.py", line 513, in parse
    raise self.error(token, e)
  File "C:\Users\kamro\Desktop\sms_a\venv\lib\site-packages\django\template\base.py", line 511, in parse
    compiled_result = compile_func(self, token)
  File "C:\Users\kamro\Desktop\sms_a\venv\lib\site-packages\django\template\defaulttags.py", line 974, in do_if
    raise TemplateSyntaxError(
django.template.exceptions.TemplateSyntaxError: Malformed template tag at line 49: "else page == 'register'"
[2022-10-06 13:08:29,043] ERROR [django.server:187] "GET /my-account/ HTTP/1.1" 500 158036
[2022-10-06 13:10:42,447] ERROR [django.request:241] Internal Server Error: /confirm-verify-code/
Traceback (most recent call last):
  File "C:\Users\kamro\Desktop\sms_a\venv\lib\site-packages\redis\connection.py", line 611, in connect
    sock = self.retry.call_with_retry(
  File "C:\Users\kamro\Desktop\sms_a\venv\lib\site-packages\redis\retry.py", line 46, in call_with_retry
    return do()
  File "C:\Users\kamro\Desktop\sms_a\venv\lib\site-packages\redis\connection.py", line 612, in <lambda>
    lambda: self._connect(), lambda error: self.disconnect(error)
  File "C:\Users\kamro\Desktop\sms_a\venv\lib\site-packages\redis\connection.py", line 677, in _connect
    raise err
  File "C:\Users\kamro\Desktop\sms_a\venv\lib\site-packages\redis\connection.py", line 665, in _connect
    sock.connect(socket_address)
ConnectionRefusedError: [WinError 10061] No connection could be made because the target machine actively refused it

During handling of the above exception, another exception occurred:

Traceback (most recent call last):
  File "C:\Users\kamro\Desktop\sms_a\venv\lib\site-packages\django\core\handlers\exception.py", line 55, in inner
    response = get_response(request)
  File "C:\Users\kamro\Desktop\sms_a\venv\lib\site-packages\django\core\handlers\base.py", line 197, in _get_response
    response = wrapped_callback(request, *callback_args, **callback_kwargs)
  File "C:\Users\kamro\Desktop\sms_a\users\views.py", line 153, in verifyView
    checked: bool = redis._check_code_in_redis(session_id, code)
  File "C:\Users\kamro\Desktop\sms_a\users\redis.py", line 38, in _check_code_in_redis
    code_in_redis: str = self.__redis.get(session_id)
  File "C:\Users\kamro\Desktop\sms_a\venv\lib\site-packages\redis\commands\core.py", line 1705, in get
    return self.execute_command("GET", name)
  File "C:\Users\kamro\Desktop\sms_a\venv\lib\site-packages\redis\client.py", line 1235, in execute_command
    conn = self.connection or pool.get_connection(command_name, **options)
  File "C:\Users\kamro\Desktop\sms_a\venv\lib\site-packages\redis\connection.py", line 1387, in get_connection
    connection.connect()
  File "C:\Users\kamro\Desktop\sms_a\venv\lib\site-packages\redis\connection.py", line 617, in connect
    raise ConnectionError(self._error_message(e))
redis.exceptions.ConnectionError: Error 10061 connecting to 127.0.0.1:6379. No connection could be made because the target machine actively refused it.
[2022-10-06 13:10:42,544] ERROR [django.server:187] "GET /confirm-verify-code/ HTTP/1.1" 500 126308
[2022-10-06 13:11:04,425] ERROR [django.request:241] Internal Server Error: /confirm-verify-code/
Traceback (most recent call last):
  File "C:\Users\kamro\Desktop\sms_a\venv\lib\site-packages\django\core\handlers\exception.py", line 55, in inner
    response = get_response(request)
  File "C:\Users\kamro\Desktop\sms_a\venv\lib\site-packages\django\core\handlers\base.py", line 197, in _get_response
    response = wrapped_callback(request, *callback_args, **callback_kwargs)
  File "C:\Users\kamro\Desktop\sms_a\users\views.py", line 153, in verifyView
    checked: bool = redis._check_code_in_redis(session_id, code)
  File "C:\Users\kamro\Desktop\sms_a\users\redis.py", line 38, in _check_code_in_redis
    code_in_redis: str = self.__redis.get(session_id)
  File "C:\Users\kamro\Desktop\sms_a\venv\lib\site-packages\redis\commands\core.py", line 1705, in get
    return self.execute_command("GET", name)
  File "C:\Users\kamro\Desktop\sms_a\venv\lib\site-packages\redis\client.py", line 1235, in execute_command
    conn = self.connection or pool.get_connection(command_name, **options)
  File "C:\Users\kamro\Desktop\sms_a\venv\lib\site-packages\redis\connection.py", line 1387, in get_connection
    connection.connect()
  File "C:\Users\kamro\Desktop\sms_a\venv\lib\site-packages\redis\connection.py", line 623, in connect
    self.on_connect()
  File "C:\Users\kamro\Desktop\sms_a\venv\lib\site-packages\redis\connection.py", line 713, in on_connect
    auth_response = self.read_response()
  File "C:\Users\kamro\Desktop\sms_a\venv\lib\site-packages\redis\connection.py", line 839, in read_response
    raise response
redis.exceptions.ResponseError: AUTH <password> called without any password configured for the default user. Are you sure your configuration is correct?
[2022-10-06 13:11:04,507] ERROR [django.server:187] "GET /confirm-verify-code/ HTTP/1.1" 500 112420
[2022-10-06 13:12:12,798] ERROR [django.request:241] Internal Server Error: /confirm-verify-code/
Traceback (most recent call last):
  File "C:\Users\kamro\Desktop\sms_a\venv\lib\site-packages\django\core\handlers\exception.py", line 55, in inner
    response = get_response(request)
  File "C:\Users\kamro\Desktop\sms_a\venv\lib\site-packages\django\core\handlers\base.py", line 197, in _get_response
    response = wrapped_callback(request, *callback_args, **callback_kwargs)
  File "C:\Users\kamro\Desktop\sms_a\users\views.py", line 153, in verifyView
    checked: bool = redis._check_code_in_redis(session_id, code)
  File "C:\Users\kamro\Desktop\sms_a\users\redis.py", line 38, in _check_code_in_redis
    code_in_redis: str = self.__redis.get(session_id)
  File "C:\Users\kamro\Desktop\sms_a\venv\lib\site-packages\redis\commands\core.py", line 1705, in get
    return self.execute_command("GET", name)
  File "C:\Users\kamro\Desktop\sms_a\venv\lib\site-packages\redis\client.py", line 1235, in execute_command
    conn = self.connection or pool.get_connection(command_name, **options)
  File "C:\Users\kamro\Desktop\sms_a\venv\lib\site-packages\redis\connection.py", line 1387, in get_connection
    connection.connect()
  File "C:\Users\kamro\Desktop\sms_a\venv\lib\site-packages\redis\connection.py", line 623, in connect
    self.on_connect()
  File "C:\Users\kamro\Desktop\sms_a\venv\lib\site-packages\redis\connection.py", line 713, in on_connect
    auth_response = self.read_response()
  File "C:\Users\kamro\Desktop\sms_a\venv\lib\site-packages\redis\connection.py", line 839, in read_response
    raise response
redis.exceptions.ResponseError: AUTH <password> called without any password configured for the default user. Are you sure your configuration is correct?
[2022-10-06 13:12:12,912] ERROR [django.server:187] "GET /confirm-verify-code/ HTTP/1.1" 500 112391
[2022-10-06 13:43:31,075] ERROR [django.request:241] Internal Server Error: /confirm-verify-code/
Traceback (most recent call last):
  File "C:\Users\kamro\Desktop\sms_a\venv\lib\site-packages\django\core\handlers\exception.py", line 55, in inner
    response = get_response(request)
  File "C:\Users\kamro\Desktop\sms_a\venv\lib\site-packages\django\core\handlers\base.py", line 197, in _get_response
    response = wrapped_callback(request, *callback_args, **callback_kwargs)
  File "C:\Users\kamro\Desktop\sms_a\users\views.py", line 153, in verifyView
    checked: bool = redis._check_code_in_redis(session_id, code)
  File "C:\Users\kamro\Desktop\sms_a\users\redis.py", line 38, in _check_code_in_redis
    code_in_redis: str = self.__redis.get(session_id)
  File "C:\Users\kamro\Desktop\sms_a\venv\lib\site-packages\redis\commands\core.py", line 1705, in get
    return self.execute_command("GET", name)
  File "C:\Users\kamro\Desktop\sms_a\venv\lib\site-packages\redis\client.py", line 1235, in execute_command
    conn = self.connection or pool.get_connection(command_name, **options)
  File "C:\Users\kamro\Desktop\sms_a\venv\lib\site-packages\redis\connection.py", line 1387, in get_connection
    connection.connect()
  File "C:\Users\kamro\Desktop\sms_a\venv\lib\site-packages\redis\connection.py", line 623, in connect
    self.on_connect()
  File "C:\Users\kamro\Desktop\sms_a\venv\lib\site-packages\redis\connection.py", line 713, in on_connect
    auth_response = self.read_response()
  File "C:\Users\kamro\Desktop\sms_a\venv\lib\site-packages\redis\connection.py", line 839, in read_response
    raise response
redis.exceptions.ResponseError: AUTH <password> called without any password configured for the default user. Are you sure your configuration is correct?
[2022-10-06 13:43:31,175] ERROR [django.server:187] "GET /confirm-verify-code/ HTTP/1.1" 500 112392
[2022-10-06 14:15:37,702] ERROR [django.request:241] Internal Server Error: /my-account/register/
Traceback (most recent call last):
  File "C:\Users\kamro\Desktop\sms_a\venv\lib\site-packages\django\core\handlers\exception.py", line 55, in inner
    response = get_response(request)
  File "C:\Users\kamro\Desktop\sms_a\venv\lib\site-packages\django\core\handlers\base.py", line 197, in _get_response
    response = wrapped_callback(request, *callback_args, **callback_kwargs)
  File "C:\Users\kamro\Desktop\sms_a\users\views.py", line 143, in registerView
    return render(request, 'users/login.html')
  File "C:\Users\kamro\Desktop\sms_a\venv\lib\site-packages\django\shortcuts.py", line 24, in render
    content = loader.render_to_string(template_name, context, request, using=using)
  File "C:\Users\kamro\Desktop\sms_a\venv\lib\site-packages\django\template\loader.py", line 61, in render_to_string
    template = get_template(template_name, using=using)
  File "C:\Users\kamro\Desktop\sms_a\venv\lib\site-packages\django\template\loader.py", line 15, in get_template
    return engine.get_template(template_name)
  File "C:\Users\kamro\Desktop\sms_a\venv\lib\site-packages\django\template\backends\django.py", line 34, in get_template
    return Template(self.engine.get_template(template_name), self)
  File "C:\Users\kamro\Desktop\sms_a\venv\lib\site-packages\django\template\engine.py", line 175, in get_template
    template, origin = self.find_template(template_name)
  File "C:\Users\kamro\Desktop\sms_a\venv\lib\site-packages\django\template\engine.py", line 157, in find_template
    template = loader.get_template(name, skip=skip)
  File "C:\Users\kamro\Desktop\sms_a\venv\lib\site-packages\django\template\loaders\cached.py", line 57, in get_template
    template = super().get_template(template_name, skip)
  File "C:\Users\kamro\Desktop\sms_a\venv\lib\site-packages\django\template\loaders\base.py", line 28, in get_template
    return Template(
  File "C:\Users\kamro\Desktop\sms_a\venv\lib\site-packages\django\template\base.py", line 154, in __init__
    self.nodelist = self.compile_nodelist()
  File "C:\Users\kamro\Desktop\sms_a\venv\lib\site-packages\django\template\base.py", line 200, in compile_nodelist
    return parser.parse()
  File "C:\Users\kamro\Desktop\sms_a\venv\lib\site-packages\django\template\base.py", line 513, in parse
    raise self.error(token, e)
  File "C:\Users\kamro\Desktop\sms_a\venv\lib\site-packages\django\template\base.py", line 511, in parse
    compiled_result = compile_func(self, token)
  File "C:\Users\kamro\Desktop\sms_a\venv\lib\site-packages\django\template\defaulttags.py", line 974, in do_if
    raise TemplateSyntaxError(
django.template.exceptions.TemplateSyntaxError: Malformed template tag at line 49: "else page"
[2022-10-06 14:15:37,798] ERROR [django.server:187] "GET /my-account/register/ HTTP/1.1" 500 157479
[2022-10-06 14:19:12,454] ERROR [django.request:241] Internal Server Error: /confirm-verify-code/
Traceback (most recent call last):
  File "C:\Users\kamro\Desktop\sms_a\venv\lib\site-packages\django\core\handlers\exception.py", line 55, in inner
    response = get_response(request)
  File "C:\Users\kamro\Desktop\sms_a\venv\lib\site-packages\django\core\handlers\base.py", line 197, in _get_response
    response = wrapped_callback(request, *callback_args, **callback_kwargs)
  File "C:\Users\kamro\Desktop\sms_a\users\views.py", line 153, in verifyView
    checked: bool = redis._check_code_in_redis(session_id, code)
  File "C:\Users\kamro\Desktop\sms_a\users\redis.py", line 39, in _check_code_in_redis
    print(f"Code in redis: {str(code_in_redis.decode('utf-8'))}")
AttributeError: 'NoneType' object has no attribute 'decode'
[2022-10-06 14:19:12,579] ERROR [django.server:187] "POST /confirm-verify-code/ HTTP/1.1" 500 88192
[2022-10-06 16:39:57,435] ERROR [django.request:241] Internal Server Error: /confirm-verify-code/
Traceback (most recent call last):
  File "C:\Users\kamro\Desktop\sms_a\venv\lib\site-packages\django\core\handlers\exception.py", line 55, in inner
    response = get_response(request)
  File "C:\Users\kamro\Desktop\sms_a\venv\lib\site-packages\django\core\handlers\base.py", line 197, in _get_response
    response = wrapped_callback(request, *callback_args, **callback_kwargs)
  File "C:\Users\kamro\Desktop\sms_a\users\views.py", line 153, in verifyView
    checked: bool = redis._check_code_in_redis(session_id, code)
  File "C:\Users\kamro\Desktop\sms_a\users\redis.py", line 39, in _check_code_in_redis
    print(f"Code in redis: {str(code_in_redis.decode('utf-8'))}")
AttributeError: 'NoneType' object has no attribute 'decode'
[2022-10-06 16:39:57,558] ERROR [django.server:187] "POST /confirm-verify-code/ HTTP/1.1" 500 88382
